<?xml version="1.0" ?>
<!-- =================================================================================== -->
<!-- |    This document was autogenerated by xacro from pioneer3at.xacro               | -->
<!-- |    EDITING THIS FILE BY HAND IS NOT RECOMMENDED                                 | -->
<!-- =================================================================================== -->
<robot name="pioneer3at" xmlns:controller="http://playerstage.sourceforge.net/gazebo/xmlschema/#controller" xmlns:interface="http://playerstage.sourceforge.net/gazebo/xmlschema/#interface" xmlns:sensor="http://playerstage.sourceforge.net/gazebo/xmlschema/#sensor">
  <!-- Chassis -->
  <link name="base_link">
    <inertial>
      <mass value="10.0"/>
      <origin xyz="0 0 0.177"/>
      <inertia ixx="0.3338" ixy="0.0" ixz="0.0" iyy="0.4783" iyz="0.0" izz="0.3338"/>
    </inertial>
    <visual>
      <origin rpy="0 0 0" xyz="0 0 0.177"/>
      <geometry name="pioneer_geom">
        <mesh filename="package://p2os_urdf/meshes/p3at_meshes/chassis.stl"/>
      </geometry>
      <material name="ChassisRed">
        <color rgba="0.851 0.0 0.0 1.0"/>
      </material>
    </visual>
    <collision>
      <origin rpy="0 0 0" xyz="0 0 0.177"/>
      <geometry>
        <mesh filename="package://p2os_urdf/meshes/p3at_meshes/chassis.stl"/>
      </geometry>
    </collision>
  </link>
  <gazebo reference="base_link">
    <material value="Gazebo/Red"/>
  </gazebo>
  <!-- Top -->
  <link name="top_plate">
    <inertial>
      <mass value="0.1"/>
      <origin xyz="-0.025 0 -0.223"/>
      <inertia ixx="1.0" ixy="0.0" ixz="0.0" iyy="1.0" iyz="0.0" izz="1.0"/>
    </inertial>
    <visual>
      <origin rpy="0 0 0" xyz="0 0 0"/>
      <geometry name="pioneer_geom">
        <mesh filename="package://p2os_urdf/meshes/p3at_meshes/top.stl"/>
      </geometry>
      <material name="TopBlack">
        <color rgba="0.038 0.038 0.038 1.0"/>
      </material>
    </visual>
    <collision>
      <origin rpy="0 0 0" xyz="0 0 0"/>
      <geometry>
        <box size="0 0 0"/>
      </geometry>
    </collision>
  </link>
  <gazebo reference="top_plate">
    <material value="Gazebo/Black"/>
  </gazebo>
  <joint name="base_top_joint" type="fixed">
    <origin rpy="0 0 0" xyz="0.003 0 0.274"/>
    <parent link="base_link"/>
    <child link="top_plate"/>
  </joint>
  <!-- Front + Back Sonar -->
  <link name="front_sonar">
    <inertial>
      <mass value="0.1"/>
      <origin xyz="0 0 0"/>
      <inertia ixx="1.0" ixy="0.0" ixz="0.0" iyy="1.0" iyz="0.0" izz="1.0"/>
    </inertial>
    <visual>
      <origin rpy="0 0 0" xyz="0 0 0"/>
      <geometry name="pioneer_geom">
        <mesh filename="package://p2os_urdf/meshes/p3at_meshes/front_sonar.stl"/>
      </geometry>
      <material name="SonarYellow">
        <color rgba="0.715 0.583 0.210 1.0"/>
      </material>
    </visual>
    <collision>
      <origin rpy="0 0 0" xyz="0 0 0"/>
      <geometry>
        <box size="0 0 0"/>
      </geometry>
    </collision>
  </link>
  <gazebo reference="front_sonar">
    <material value="Gazebo/Yellow"/>
  </gazebo>
  <joint name="base_front_joint" type="fixed">
    <origin rpy="0 0 0" xyz="0.193 0 0.25"/>
    <parent link="base_link"/>
    <child link="front_sonar"/>
  </joint>
  <link name="back_sonar">
    <inertial>
      <mass value="0.1"/>
      <origin xyz="0 0 0"/>
      <inertia ixx="1.0" ixy="0.0" ixz="0.0" iyy="1.0" iyz="0.0" izz="1.0"/>
    </inertial>
    <visual>
      <origin rpy="0 0 0" xyz="0 0 0"/>
      <geometry name="pioneer_geom">
        <mesh filename="package://p2os_urdf/meshes/p3at_meshes/back_sonar.stl"/>
      </geometry>
      <material name="SonarYellow">
        <color rgba="0.715 0.583 0.210 1.0"/>
      </material>
    </visual>
    <collision>
      <origin rpy="0 0 0" xyz="0 0 0"/>
      <geometry>
        <box size="0 0 0"/>
      </geometry>
    </collision>
  </link>
  <gazebo reference="back_sonar">
    <material value="Gazebo/Yellow"/>
  </gazebo>
  <joint name="base_back_joint" type="fixed">
    <origin rpy="0 0 0" xyz="-0.187 0 0.247"/>
    <parent link="base_link"/>
    <child link="back_sonar"/>
  </joint>
  <joint name="velodyne_base_mount_joint" type="fixed">
    <origin rpy="0 0 0" xyz="0 0 0.15"/>
    <parent link="support"/>
    <child link="velodyne_base_link"/>
  </joint>
  <link name="velodyne_base_link">
    <inertial>
      <mass value="0.83"/>
      <origin xyz="0 0 0.03585"/>
      <inertia ixx="0.000908059425" ixy="0" ixz="0" iyy="0.000908059425" iyz="0" izz="0.0011049624"/>
    </inertial>
    <visual>
      <geometry>
        <mesh filename="package://velodyne_description/meshes/VLP16_base_1.dae"/>
      </geometry>
    </visual>
    <visual>
      <geometry>
        <mesh filename="package://velodyne_description/meshes/VLP16_base_2.dae"/>
      </geometry>
    </visual>
    <collision>
      <origin rpy="0 0 0" xyz="0 0 0.03585"/>
      <geometry>
        <cylinder length="0.0717" radius="0.0516"/>
      </geometry>
    </collision>
  </link>
  <joint name="velodyne_base_scan_joint" type="fixed">
    <origin rpy="0 0 0" xyz="0 0 0.0377"/>
    <!-- <origin xyz="0.1 0 0.0377" rpy="0 0 0" /> -->
    <parent link="velodyne_base_link"/>
    <child link="velodyne"/>
  </joint>
  <link name="velodyne">
    <inertial>
      <mass value="0.01"/>
      <origin xyz="0 0 0"/>
      <inertia ixx="1e-7" ixy="0" ixz="0" iyy="1e-7" iyz="0" izz="1e-7"/>
    </inertial>
    <visual>
      <origin xyz="0 0 -0.0377"/>
      <geometry>
        <mesh filename="package://velodyne_description/meshes/VLP16_scan.dae"/>
      </geometry>
    </visual>
  </link>
  <!-- Gazebo requires the velodyne_gazebo_plugins package -->
  <gazebo reference="velodyne">
    <sensor name="velodyne-VLP16" type="ray">
      <pose>0 0 0 0 0 0</pose>
      <visualize>false</visualize>
      <update_rate>5</update_rate>
      <ray>
        <scan>
          <horizontal>
            <samples>350</samples>
            <resolution>1</resolution>
            <min_angle>-3.141592653589793</min_angle>
            <max_angle>3.141592653589793</max_angle>
          </horizontal>
          <vertical>
            <samples>16</samples>
            <resolution>1</resolution>
            <min_angle>-0.2617993877991494</min_angle>
            <max_angle> 0.2617993877991494</max_angle>
          </vertical>
        </scan>
        <range>
          <min>0.3</min>
          <max>131.0</max>
          <resolution>0.001</resolution>
        </range>
        <noise>
          <type>gaussian</type>
          <mean>0.0</mean>
          <stddev>0.0</stddev>
        </noise>
      </ray>
      <plugin filename="libgazebo_ros_velodyne_laser.so" name="gazebo_ros_laser_controller">
        <topicName>velodyne_points</topicName>
        <frameName>velodyne</frameName>
        <organize_cloud>True</organize_cloud>
        <min_range>0.1</min_range>
        <max_range>130.0</max_range>
        <gaussianNoise>0.008</gaussianNoise>
      </plugin>
    </sensor>
  </gazebo>
  <!--Gazebo Hokuyo Laser Plugin-->
  <gazebo reference="sensor_laser">
    <!-- <sensor type="gpu_ray" name="head_hokuyo_sensor"> -->
    <sensor name="head_hokuyo_sensor" type="ray">
      <pose>0 0 0 0 0 0</pose>
      <visualize>false</visualize>
      <update_rate>25.0</update_rate>
      <ray>
        <scan>
          <horizontal>
            <samples>720</samples>
            <resolution>1</resolution>
            <min_angle>-3.141593</min_angle>
            <max_angle>3.141593</max_angle>
          </horizontal>
        </scan>
        <range>
          <min>0.10</min>
          <max>30.0</max>
          <resolution>0.01</resolution>
        </range>
        <noise>
          <type>gaussian</type>
          <mean>0.0</mean>
          <stddev>0.01</stddev>
          <!-- 0.01 -->
        </noise>
      </ray>
      <!-- <plugin name="gazebo_ros_head_hokuyo_controller" filename="libgazebo_ros_gpu_laser.so"> -->
      <plugin filename="libgazebo_ros_laser.so" name="gazebo_ros_head_hokuyo_controller">
        <topicName>laser_scan</topicName>
        <frameName>/sensor_laser</frameName>
      </plugin>
    </sensor>
  </gazebo>
  <link name="p3at_front_left_axle">
    <inertial>
      <mass value="0.1"/>
      <origin xyz="0 0 0"/>
      <inertia ixx="1.0" ixy="0.0" ixz="0.0" iyy="1.0" iyz="0.0" izz="1.0"/>
    </inertial>
    <visual>
      <origin rpy="0 0 0" xyz="0 0 0"/>
      <geometry name="pioneer_geom">
        <mesh filename="package://p2os_urdf/meshes/p3at_meshes/axle.stl"/>
      </geometry>
      <material name="AxleGrey">
        <color rgba="0.5 0.5 0.5 1"/>
      </material>
    </visual>
    <collision>
      <origin rpy="0 0 0" xyz="0 0 0"/>
      <geometry>
        <box size="0 0 0"/>
      </geometry>
    </collision>
  </link>
  <gazebo reference="p3at_front_left_axle">
    <material value="Gazebo/Grey"/>
  </gazebo>
  <joint name="base_front_left_axle_joint" type="fixed">
    <origin rpy="0 0 0" xyz="0.135 0.156 0.111"/>
    <parent link="base_link"/>
    <child link="p3at_front_left_axle"/>
  </joint>
  <link name="p3at_front_left_hub">
    <inertial>
      <mass value="0.1"/>
      <origin xyz="0 0 0"/>
      <inertia ixx="1.0" ixy="0.0" ixz="0.0" iyy="1.0" iyz="0.0" izz="1.0"/>
    </inertial>
    <visual>
      <origin rpy="0 0 0" xyz="0 0 0"/>
      <geometry name="pioneer_geom">
        <mesh filename="package://p2os_urdf/meshes/p3at_meshes/left_hubcap.stl"/>
      </geometry>
      <material name="HubcapYellow">
        <color rgba="1.0 0.811 0.151 1.0"/>
      </material>
    </visual>
    <collision>
      <origin rpy="0 0 0" xyz="0 0 0"/>
      <geometry>
        <box size="0 0 0"/>
      </geometry>
    </collision>
  </link>
  <gazebo reference="p3at_front_left_hub">
    <material value="Gazebo/Yellow"/>
  </gazebo>
  <joint name="base_front_left_hub_joint" type="fixed">
    <origin rpy="0 0 0" xyz="0 0.041 0"/>
    <parent link="p3at_front_left_axle"/>
    <child link="p3at_front_left_hub"/>
  </joint>
  <link name="p3at_front_left_wheel">
    <inertial>
      <mass value="0.5"/>
      <origin xyz="0 0 0"/>
      <inertia ixx="0.012411765597" ixy="0" ixz="0" iyy="0.015218160428" iyz="0" izz="0.011763977943"/>
    </inertial>
    <visual>
      <origin rpy="0 0 0" xyz="0 0 0"/>
      <geometry name="pioneer_geom">
        <mesh filename="package://p2os_urdf/meshes/p3at_meshes/wheel.stl"/>
      </geometry>
      <material name="WheelBlack">
        <color rgba="0.117 0.117 0.117 1"/>
      </material>
    </visual>
    <collision>
      <origin rpy="-1.57079635 0 0" xyz="0 0 0"/>
      <geometry>
        <!--mesh filename="package://p2os_urdf/meshes/p3at_meshes/wheel.stl"/-->
        <cylinder length="0.075" radius="0.111"/>
      </geometry>
    </collision>
  </link>
  <gazebo reference="p3at_front_left_wheel">
    <material value="Gazebo/Black"/>
  </gazebo>
  <joint name="p3at_front_left_wheel_joint" type="continuous">
    <axis xyz="0 1 0"/>
    <anchor xyz="0 0 0"/>
    <limit effort="100" velocity="100"/>
    <joint_properties damping="0.7"/>
    <origin rpy="0 0 0" xyz="0 0 0"/>
    <parent link="p3at_front_left_hub"/>
    <child link="p3at_front_left_wheel"/>
  </joint>
  <link name="p3at_front_right_axle">
    <inertial>
      <mass value="0.1"/>
      <origin xyz="0 0 0"/>
      <inertia ixx="1.0" ixy="0.0" ixz="0.0" iyy="1.0" iyz="0.0" izz="1.0"/>
    </inertial>
    <visual>
      <origin rpy="0 0 0" xyz="0 0 0"/>
      <geometry name="pioneer_geom">
        <mesh filename="package://p2os_urdf/meshes/p3at_meshes/axle.stl"/>
      </geometry>
      <material name="AxleGrey">
        <color rgba="0.5 0.5 0.5 1"/>
      </material>
    </visual>
    <collision>
      <origin rpy="0 0 0" xyz="0 0 0"/>
      <geometry>
        <box size="0 0 0"/>
      </geometry>
    </collision>
  </link>
  <gazebo reference="p3at_front_right_axle">
    <material value="Gazebo/Grey"/>
  </gazebo>
  <joint name="base_front_right_axle_joint" type="fixed">
    <origin rpy="0 0 0" xyz="0.135 -0.156 0.111"/>
    <parent link="base_link"/>
    <child link="p3at_front_right_axle"/>
  </joint>
  <link name="p3at_front_right_hub">
    <inertial>
      <mass value="0.1"/>
      <origin xyz="0 0 0"/>
      <inertia ixx="1.0" ixy="0.0" ixz="0.0" iyy="1.0" iyz="0.0" izz="1.0"/>
    </inertial>
    <visual>
      <origin rpy="0 0 0" xyz="0 0 0"/>
      <geometry name="pioneer_geom">
        <mesh filename="package://p2os_urdf/meshes/p3at_meshes/right_hubcap.stl"/>
      </geometry>
      <material name="HubcapYellow">
        <color rgba="1.0 0.811 0.151 1.0"/>
      </material>
    </visual>
    <collision>
      <origin rpy="0 0 0" xyz="0 0 0"/>
      <geometry>
        <box size="0 0 0"/>
      </geometry>
    </collision>
  </link>
  <gazebo reference="p3at_front_right_hub">
    <material value="Gazebo/Yellow"/>
  </gazebo>
  <joint name="base_front_right_hub_joint" type="fixed">
    <origin rpy="0 0 0" xyz="0 -0.041 0"/>
    <parent link="p3at_front_right_axle"/>
    <child link="p3at_front_right_hub"/>
  </joint>
  <link name="p3at_front_right_wheel">
    <inertial>
      <mass value="0.5"/>
      <origin xyz="0 0 0"/>
      <inertia ixx="0.012411765597" ixy="0" ixz="0" iyy="0.015218160428" iyz="0" izz="0.011763977943"/>
    </inertial>
    <visual>
      <origin rpy="0 0 0" xyz="0 0 0"/>
      <geometry name="pioneer_geom">
        <mesh filename="package://p2os_urdf/meshes/p3at_meshes/wheel.stl"/>
      </geometry>
      <material name="WheelBlack">
        <color rgba="0.117 0.117 0.117 1"/>
      </material>
    </visual>
    <collision>
      <origin rpy="-1.57079635 0 0" xyz="0 0 0"/>
      <geometry>
        <!--mesh filename="package://p2os_urdf/meshes/p3at_meshes/wheel.stl"/-->
        <cylinder length="0.075" radius="0.111"/>
      </geometry>
    </collision>
  </link>
  <gazebo reference="p3at_front_right_wheel">
    <material value="Gazebo/Black"/>
  </gazebo>
  <joint name="p3at_front_right_wheel_joint" type="continuous">
    <axis xyz="0 1 0"/>
    <anchor xyz="0 0 0"/>
    <limit effort="100" velocity="100"/>
    <joint_properties damping="0.7"/>
    <origin rpy="0 0 0" xyz="0 0 0"/>
    <parent link="p3at_front_right_hub"/>
    <child link="p3at_front_right_wheel"/>
  </joint>
  <link name="p3at_back_left_axle">
    <inertial>
      <mass value="0.1"/>
      <origin xyz="0 0 0"/>
      <inertia ixx="1.0" ixy="0.0" ixz="0.0" iyy="1.0" iyz="0.0" izz="1.0"/>
    </inertial>
    <visual>
      <origin rpy="0 0 0" xyz="0 0 0"/>
      <geometry name="pioneer_geom">
        <mesh filename="package://p2os_urdf/meshes/p3at_meshes/axle.stl"/>
      </geometry>
      <material name="AxleGrey">
        <color rgba="0.5 0.5 0.5 1"/>
      </material>
    </visual>
    <collision>
      <origin rpy="0 0 0" xyz="0 0 0"/>
      <geometry>
        <mesh filename="package://p2os_urdf/meshes/p3at_meshes/axle.stl"/>
      </geometry>
    </collision>
  </link>
  <gazebo reference="p3at_back_left_axle">
    <material value="Gazebo/Grey"/>
  </gazebo>
  <joint name="bp3at_back_left_axle_joint" type="fixed">
    <origin rpy="0 0 0" xyz="-0.134 0.156 0.111"/>
    <parent link="base_link"/>
    <child link="p3at_back_left_axle"/>
  </joint>
  <link name="p3at_back_left_hub">
    <inertial>
      <mass value="0.1"/>
      <origin xyz="0 0 0"/>
      <inertia ixx="1.0" ixy="0.0" ixz="0.0" iyy="1.0" iyz="0.0" izz="1.0"/>
    </inertial>
    <visual>
      <origin rpy="0 0 0" xyz="0 0 0"/>
      <geometry name="pioneer_geom">
        <mesh filename="package://p2os_urdf/meshes/p3at_meshes/left_hubcap.stl"/>
      </geometry>
      <material name="HubcapYellow"/>
    </visual>
    <collision>
      <origin rpy="0 0 0" xyz="0 0 0"/>
      <geometry>
        <mesh filename="package://p2os_urdf/meshes/p3at_meshes/left_hubcap.stl"/>
      </geometry>
    </collision>
  </link>
  <gazebo reference="p3at_back_left_hub">
    <material value="Gazebo/Yellow"/>
  </gazebo>
  <joint name="p3at_back_left_hub_joint" type="fixed">
    <origin rpy="0 0 0" xyz="-0 0.041 0"/>
    <parent link="p3at_back_left_axle"/>
    <child link="p3at_back_left_hub"/>
  </joint>
  <link name="p3at_back_left_wheel">
    <inertial>
      <mass value="0.5"/>
      <origin xyz="0 0 0"/>
      <inertia ixx="0.012411765597" ixy="0" ixz="0" iyy="0.015218160428" iyz="0" izz="0.011763977943"/>
    </inertial>
    <visual>
      <origin rpy="0 0 0" xyz="0 0 0"/>
      <geometry name="pioneer_geom">
        <mesh filename="package://p2os_urdf/meshes/p3at_meshes/wheel.stl"/>
      </geometry>
      <material name="WheelBlack"/>
    </visual>
    <collision>
      <origin rpy="-1.57079635 0 0" xyz="0 0 0"/>
      <geometry>
        <!--mesh filename="package://p2os_urdf/meshes/p3at_meshes/wheel.stl"/-->
        <cylinder length="0.075" radius="0.111"/>
      </geometry>
    </collision>
  </link>
  <gazebo reference="p3at_back_left_wheel">
    <material value="Gazebo/Black"/>
  </gazebo>
  <joint name="p3at_back_left_wheel_joint" type="continuous">
    <axis xyz="0 1 0"/>
    <anchor xyz="0 0 0"/>
    <limit effort="100" velocity="100"/>
    <joint_properties damping="0.7"/>
    <origin rpy="0 0 0" xyz="0 0 0"/>
    <parent link="p3at_back_left_hub"/>
    <child link="p3at_back_left_wheel"/>
  </joint>
  <gazebo reference="p3at_back_left_wheel">
    <kp>1000000.0</kp>
    <!-- kp and kd for rubber -->
    <kd>100.0</kd>
    <mu1>10.0</mu1>
    <mu2>1.0</mu2>
    <fdir1>0 1 0</fdir1>
    <!-- is this correct? -->
    <maxVel>1.0</maxVel>
    <minDepth>0.00</minDepth>
  </gazebo>
  <gazebo reference="p3at_front_left_wheel">
    <kp>1000000.0</kp>
    <!-- kp and kd for rubber -->
    <kd>100.0</kd>
    <mu1>10.0</mu1>
    <mu2>1.0</mu2>
    <fdir1>0 1 0</fdir1>
    <!-- is this correct? -->
    <maxVel>1.0</maxVel>
    <minDepth>0.00</minDepth>
  </gazebo>
  <link name="p3at_back_right_axle">
    <inertial>
      <mass value="0.1"/>
      <origin xyz="0 0 0"/>
      <inertia ixx="1.0" ixy="0.0" ixz="0.0" iyy="1.0" iyz="0.0" izz="1.0"/>
    </inertial>
    <visual>
      <origin rpy="0 0 0" xyz="0 0 0"/>
      <geometry name="pioneer_geom">
        <mesh filename="package://p2os_urdf/meshes/p3at_meshes/axle.stl"/>
      </geometry>
      <material name="AxleGrey">
        <color rgba="0.5 0.5 0.5 1"/>
      </material>
    </visual>
    <collision>
      <origin rpy="0 0 0" xyz="0 0 0"/>
      <geometry>
        <mesh filename="package://p2os_urdf/meshes/p3at_meshes/axle.stl"/>
      </geometry>
    </collision>
  </link>
  <gazebo reference="p3at_back_right_axle">
    <material value="Gazebo/Grey"/>
  </gazebo>
  <joint name="bp3at_back_right_axle_joint" type="fixed">
    <origin rpy="0 0 0" xyz="-0.134 -0.156 0.111"/>
    <parent link="base_link"/>
    <child link="p3at_back_right_axle"/>
  </joint>
  <link name="p3at_back_right_hub">
    <inertial>
      <mass value="0.1"/>
      <origin xyz="0 0 0"/>
      <inertia ixx="1.0" ixy="0.0" ixz="0.0" iyy="1.0" iyz="0.0" izz="1.0"/>
    </inertial>
    <visual>
      <origin rpy="0 0 0" xyz="0 0 0"/>
      <geometry name="pioneer_geom">
        <mesh filename="package://p2os_urdf/meshes/p3at_meshes/right_hubcap.stl"/>
      </geometry>
      <material name="HubcapYellow"/>
    </visual>
    <collision>
      <origin rpy="0 0 0" xyz="0 0 0"/>
      <geometry>
        <mesh filename="package://p2os_urdf/meshes/p3at_meshes/right_hubcap.stl"/>
      </geometry>
    </collision>
  </link>
  <gazebo reference="p3at_back_right_hub">
    <material value="Gazebo/Yellow"/>
  </gazebo>
  <joint name="p3at_back_right_hub_joint" type="fixed">
    <origin rpy="0 0 0" xyz="-0 -0.041 0"/>
    <parent link="p3at_back_right_axle"/>
    <child link="p3at_back_right_hub"/>
  </joint>
  <link name="p3at_back_right_wheel">
    <inertial>
      <mass value="0.5"/>
      <origin xyz="0 0 0"/>
      <inertia ixx="0.012411765597" ixy="0" ixz="0" iyy="0.015218160428" iyz="0" izz="0.011763977943"/>
    </inertial>
    <visual>
      <origin rpy="0 0 0" xyz="0 0 0"/>
      <geometry name="pioneer_geom">
        <mesh filename="package://p2os_urdf/meshes/p3at_meshes/wheel.stl"/>
      </geometry>
      <material name="WheelBlack"/>
    </visual>
    <collision>
      <origin rpy="-1.57079635 0 0" xyz="0 0 0"/>
      <geometry>
        <!--mesh filename="package://p2os_urdf/meshes/p3at_meshes/wheel.stl"/-->
        <cylinder length="0.075" radius="0.111"/>
      </geometry>
    </collision>
  </link>
  <gazebo reference="p3at_back_right_wheel">
    <material value="Gazebo/Black"/>
  </gazebo>
  <joint name="p3at_back_right_wheel_joint" type="continuous">
    <axis xyz="0 1 0"/>
    <anchor xyz="0 0 0"/>
    <limit effort="100" velocity="100"/>
    <joint_properties damping="0.7"/>
    <origin rpy="0 0 0" xyz="0 0 0"/>
    <parent link="p3at_back_right_hub"/>
    <child link="p3at_back_right_wheel"/>
  </joint>
  <gazebo reference="p3at_back_right_wheel">
    <kp>1000000.0</kp>
    <!-- kp and kd for rubber -->
    <kd>100.0</kd>
    <mu1>10.0</mu1>
    <mu2>1.0</mu2>
    <fdir1>0 1 0</fdir1>
    <!-- is this correct? -->
    <maxVel>1.0</maxVel>
    <minDepth>0.00</minDepth>
  </gazebo>
  <gazebo reference="p3at_front_right_wheel">
    <kp>1000000.0</kp>
    <!-- kp and kd for rubber -->
    <kd>100.0</kd>
    <mu1>10.0</mu1>
    <mu2>1.0</mu2>
    <fdir1>0 1 0</fdir1>
    <!-- is this correct? -->
    <maxVel>1.0</maxVel>
    <minDepth>0.00</minDepth>
  </gazebo>
  <gazebo>
    <plugin filename="libgazebo_ros_skid_steer_drive.so" name="skid_steer_drive_controller">
      <updateRate>100.0</updateRate>
      <robotNamespace>/</robotNamespace>
      <leftFrontJoint>p3at_front_left_wheel_joint</leftFrontJoint>
      <rightFrontJoint>p3at_front_right_wheel_joint</rightFrontJoint>
      <leftRearJoint>p3at_back_left_wheel_joint</leftRearJoint>
      <rightRearJoint>p3at_back_right_wheel_joint</rightRearJoint>
      <wheelSeparation>0.4</wheelSeparation>
      <wheelDiameter>0.215</wheelDiameter>
      <robotBaseFrame>base_link</robotBaseFrame>
      <torque>200</torque>
      <topicName>cmd_vel</topicName>
    </plugin>
  </gazebo>
</robot>
